Workbook

Sheet 작성 기준
B2: SSBL 런칭 체크리스트 — 작성 기준
B3: 이 문서는 런칭 D-30 전시 상황에서의 체크리스트 운영 원칙을 정의합니다.
B5: 1. 핵심 원칙
B7: 체크리스트의 목적 | C7: "뭘 할지"가 아니라 "뭘 안 할지"를 결정하는 도구. 한 달 안에 모든 것을 할 수 없다. 버릴 것을 명확히 해야 남은 것을 끝낼 수 있다.
B8: 항목의 크기 (얼마나 잘게 쪼갤 것인가) | C8: 한 명의 담당자가 완료 여부를 YES/NO로 판단할 수 있는 단위. "서버 개발 완료"는 너무 크고, "DB index 추가"는 너무 작다.
B9: 살아있는 문서 | C9: 매일 이 체크리스트 기준으로 현황 점검. "어제 뭐 끝났고, 오늘 뭐 해야 하고, 뭐가 막혀있는지" 확인.
B10: 완벽 포기, 생존 확보 | C10: 완벽한 런칭을 포기하고 "치명적 사고 없는 런칭"을 목표로 한다. 런칭 후 첫 업데이트에서 보강하는 전략을 전제한다.
B12: 2. 3단계 분류 기준
B14: [P0] 필수 — 이거 없으면 출시 불가 | C14: 이것이 안 되면 물리적으로 런칭이 불가능한 항목. 스토어 심사, 결제 동작, 서버 가동, 법적 의무(확률 공시, 이용약관 등). [!] 전체 항목의 30% 이내로 제한. 넘으면 분류가 잘못된 것.
B15: [P1] 중요 — 첫인상이 걸린 항목 | C15: 없으면 런칭은 되지만 첫인상이 심각하게 훼손되는 항목. 튜토리얼 완성도, 주요 버그 수정, 번역 품질, 런칭 이벤트. [!] "있으면 좋겠다"는 전부 [P2]로 내린다.
B16: [P2] 후속 — 출시 후 대응 가능 | C16: 런칭 후 첫 번째~두 번째 업데이트에서 대응 가능한 항목. 대부분의 편의 기능, 최적화, 부가 콘텐츠. [!] 여기에 과감하게 넣지 못하면 한 달 안에 끝나는 건 없다.
B18: 3. 담당자 상태 정의
B20: 이름 명시 | C20: 확정된 담당자. 이 사람에게 매일 진행 상황을 확인한다.
B21: 인수필요 | C21: 레거시 담당자 퇴사/이동으로 인수인계가 필요한 항목. 즉시 재배치 대상. 48시간 내 담당자를 지정하지 못하면 "포기"로 전환 검토.
B22: 미정 | C22: 아무도 잡지 않은 항목. 가장 위험한 상태. 모두가 "누군가 하겠지"라고 생각하는 항목이 런칭을 터뜨린다.
B23: 포기 | C23: 한 달 안에 불가능하다고 팀이 합의한 항목. 포기도 의사결정이다. 런칭 후 로드맵에 명시적으로 넘긴다.
B25: 4. 운영 규칙
B27: 일일 점검 | C27: 매일 이 체크리스트 기준으로 현황 점검. "어제 뭐 끝났고, 오늘 뭐 해야 하고, 뭐가 막혀있는지" 확인.
B28: 마감일 기준 | C28: 주 단위가 아니라 일 단위. "3월 셋째 주"가 아니라 "3월 17일 EOD". [P0] 필수 항목은 반드시 일 단위 마감.
B29: 정렬 기준 | C29: Tier → 마감일 순. 카테고리별 정렬 금지. "서버에서 뭘 해야 하지"가 아니라 "오늘 뭘 해야 하지"가 보여야 한다.
B30: 블로커 명시 | C30: "이게 안 끝나면 저것도 못 한다"는 관계를 블로커 컬럼에 명시. 크리티컬 패스의 가장 앞에 있는 항목이 진짜 1순위.
B31: 대표 보고 | C31: 이 체크리스트 하나로 보고. 별도 보고서 작성 금지. [P0] 항목 중 "인수필요/미정" 현황 → 의사결정 요청 포맷으로 보고.
B33: 5. Go/No-Go 판단 기준
B35: Go 조건 | C35: [P0] 필수 항목 100% 완료 + [P1] 중요 항목 80% 이상 완료. 담당 "미정" 항목이 [P0]에 0건.
B36: Conditional Go | C36: [P0] 100% 완료 + [P1] 60~80% 완료. 잔여 [P1] 항목에 대한 D+3 이내 핫픽스 플랜 확보 시 런칭 진행.
B37: No-Go | C37: [P0] 필수 항목 미완료 건 존재. 결제, 법적 의무, 스토어 심사 중 하나라도 미충족 시 런칭 연기.

Sheet 대시보드
B1: SSBL 런칭 준비 현황 대시보드
B2: 최종 업데이트: 2026-02-24 | 체크리스트 상태 변경 시 자동 반영
B4: 핵심 지표
B5: =COUNTA('런칭 체크리스트'!B5:B200) | C5: =COUNTIF('런칭 체크리스트'!G5:G200,"완료") | D5: =COUNTIF('런칭 체크리스트'!G5:G200,"진행중") | E5: =COUNTIF('런칭 체크리스트'!G5:G200,"미착수")+COUNTIF('런칭 체크리스트'!G5:G200,"블로킹") | F5: =IF(B5=0,0,C5/B5)
B6: 전체 항목 | C6: 완료 | D6: 진행중 | E6: 미착수/블로킹 | F6: 전체 완료율
B8: 구분별 현황
B9: 구분 | C9: 전체 | D9: 완료 | E9: 진행중 | F9: 미착수/블로킹 | G9: 완료율
B10: [P0] 필수 | C10: =COUNTIF('런칭 체크리스트'!A:A,B10) | D10: =COUNTIFS('런칭 체크리스트'!A:A,B10,'런칭 체크리스트'!G:G,"완료") | E10: =COUNTIFS('런칭 체크리스트'!A:A,B10,'런칭 체크리스트'!G:G,"진행중") | F10: =COUNTIFS('런칭 체크리스트'!A:A,B10,'런칭 체크리스트'!G:G,"미착수")+COUNTIFS('런칭 체크리스트'!A:A,B10,'런칭 체크리스트'!G:G,"블로킹") | G10: =IF(C10=0,0,D10/C10)
B11: [P1] 중요 | C11: =COUNTIF('런칭 체크리스트'!A:A,B11) | D11: =COUNTIFS('런칭 체크리스트'!A:A,B11,'런칭 체크리스트'!G:G,"완료") | E11: =COUNTIFS('런칭 체크리스트'!A:A,B11,'런칭 체크리스트'!G:G,"진행중") | F11: =COUNTIFS('런칭 체크리스트'!A:A,B11,'런칭 체크리스트'!G:G,"미착수")+COUNTIFS('런칭 체크리스트'!A:A,B11,'런칭 체크리스트'!G:G,"블로킹") | G11: =IF(C11=0,0,D11/C11)
B12: [P2] 후속 | C12: =COUNTIF('런칭 체크리스트'!A:A,B12) | D12: =COUNTIFS('런칭 체크리스트'!A:A,B12,'런칭 체크리스트'!G:G,"완료") | E12: =COUNTIFS('런칭 체크리스트'!A:A,B12,'런칭 체크리스트'!G:G,"진행중") | F12: =COUNTIFS('런칭 체크리스트'!A:A,B12,'런칭 체크리스트'!G:G,"미착수")+COUNTIFS('런칭 체크리스트'!A:A,B12,'런칭 체크리스트'!G:G,"블로킹") | G12: =IF(C12=0,0,D12/C12)
B13: 합계 | C13: =SUM(C10:C12) | D13: =SUM(D10:D12) | E13: =SUM(E10:E12) | F13: =SUM(F10:F12) | G13: =IF(C13=0,0,D13/C13)
B15: 담당자 리스크 현황
B16: 항목 | C16: 건수
B17: 담당자 "미정" (가장 위험) | C17: =COUNTIF('런칭 체크리스트'!D:D,"미정")
B18: 담당자 "인수필요" | C18: =COUNTIF('런칭 체크리스트'!D:D,"인수필요")
B19: 담당자 "포기" | C19: =COUNTIF('런칭 체크리스트'!D:D,"포기")
B20: "미정" 중 [P0] 필수 | C20: =COUNTIFS('런칭 체크리스트'!D:D,"미정",'런칭 체크리스트'!A:A,"[P0] 필수")
B21: "인수필요" 중 [P0] 필수 | C21: =COUNTIFS('런칭 체크리스트'!D:D,"인수필요",'런칭 체크리스트'!A:A,"[P0] 필수")
B23: 상태별 현황
B24: 상태 | C24: 건수 | D24: 비율
B25: 완료 | C25: =COUNTIF('런칭 체크리스트'!G:G,B25) | D25: =IF(COUNTA('런칭 체크리스트'!B5:B200)=0,0,C25/COUNTA('런칭 체크리스트'!B5:B200))
B26: 진행중 | C26: =COUNTIF('런칭 체크리스트'!G:G,B26) | D26: =IF(COUNTA('런칭 체크리스트'!B5:B200)=0,0,C26/COUNTA('런칭 체크리스트'!B5:B200))
B27: 미착수 | C27: =COUNTIF('런칭 체크리스트'!G:G,B27) | D27: =IF(COUNTA('런칭 체크리스트'!B5:B200)=0,0,C27/COUNTA('런칭 체크리스트'!B5:B200))
B28: 블로킹 | C28: =COUNTIF('런칭 체크리스트'!G:G,B28) | D28: =IF(COUNTA('런칭 체크리스트'!B5:B200)=0,0,C28/COUNTA('런칭 체크리스트'!B5:B200))
B29: 포기 | C29: =COUNTIF('런칭 체크리스트'!G:G,B29) | D29: =IF(COUNTA('런칭 체크리스트'!B5:B200)=0,0,C29/COUNTA('런칭 체크리스트'!B5:B200))
B32: Go / No-Go 자동 판정
B33: 판정 | C33: 조건
B34: GO | C34: [P0] 필수 100% 완료 + [P1] 중요 80% 이상 완료 + [P0] 필수 담당 미정 0건
B35: CONDITIONAL GO | C35: [P0] 필수 100% 완료 + [P1] 중요 60~80% 완료 + D+3 핫픽스 플랜 확보
B36: NO-GO | C36: [P0] 필수 미완료 건 존재 또는 결제/법적의무/스토어 심사 미충족
B38: 현재 자동 판정: | D38: =IF(AND(COUNTIF('런칭 체크리스트'!A:A,"[P0] 필수")=COUNTIFS('런칭 체크리스트'!A:A,"[P0] 필수",'런칭 체크리스트'!G:G,"완료"),COUNTIFS('런칭 체크리스트'!A:A,"[P0] 필수",'런칭 체크리스트'!D:D,"미정")=0,IF(COUNTIF('런칭 체크리스트'!A:A,"[P1] 중요")=0,TRUE(),COUNTIFS('런칭 체크리스트'!A:A,"[P1] 중요",'런칭 체크리스트'!G:G,"완료")/COUNTIF('런칭 체크리스트'!A:A,"[P1] 중요")>=0.8)),"GO",IF(AND(COUNTIF('런칭 체크리스트'!A:A,"[P0] 필수")=COUNTIFS('런칭 체크리스트'!A:A,"[P0] 필수",'런칭 체크리스트'!G:G,"완료"),IF(COUNTIF('런칭 체크리스트'!A:A,"[P1] 중요")=0,TRUE(),COUNTIFS('런칭 체크리스트'!A:A,"[P1] 중요",'런칭 체크리스트'!G:G,"완료")/COUNTIF('런칭 체크리스트'!A:A,"[P1] 중요")>=0.6)),"CONDITIONAL GO","NO-GO"))
B39: [P0] 필수 완료율: | D39: =IF(COUNTIF('런칭 체크리스트'!A:A,"[P0] 필수")=0,0,COUNTIFS('런칭 체크리스트'!A:A,"[P0] 필수",'런칭 체크리스트'!G:G,"완료")/COUNTIF('런칭 체크리스트'!A:A,"[P0] 필수"))
B40: [P1] 중요 완료율: | D40: =IF(COUNTIF('런칭 체크리스트'!A:A,"[P1] 중요")=0,0,COUNTIFS('런칭 체크리스트'!A:A,"[P1] 중요",'런칭 체크리스트'!G:G,"완료")/COUNTIF('런칭 체크리스트'!A:A,"[P1] 중요"))

Sheet 런칭 체크리스트
A1: SSBL 런칭 체크리스트 — D-30 전시 모드
A2: 최종 업데이트: 2026-02-24 | Tier→마감일 순 정렬 | 일일 점검 기준 문서
A4: 구분 | B4: 항목 | C4: 상세 | D4: 담당자 | E4: 블로커 (선행항목) | F4: 마감일 | G4: 상태 | H4: 오늘의 이슈
A5: [P0] 필수 | B5: Apple App Store 심사 제출 | C5: 릴리즈 빌드 기반 심사 제출. 리젝 시 재심사 버퍼 확보 | E5: 릴리즈 빌드 완성 | G5: 미착수
A6: [P0] 필수 | B6: Google Play Store 심사 제출 | C6: 콘텐츠 등급 설정 포함. 정책 위반 사전 체크 | E6: 릴리즈 빌드 완성 | G6: 미착수
A7: [P0] 필수 | B7: Release 빌드 생성 및 검증 | C7: 디버그 코드 제거, 난독화, ProGuard/R8 적용 | E7: 크리티컬 버그 픽스 | G7: 미착수
A8: [P0] 필수 | B8: 프로덕션 서버 구축 및 가동 | C8: 오토스케일링, CDN, 프로덕션 DB 세팅 | G8: 미착수
A9: [P0] 필수 | B9: 서버 부하 테스트 | C9: 목표 CCU 대비 150% 부하 테스트. 병목 해소 | E9: 프로덕션 서버 구축 | G9: 미착수
A10: [P0] 필수 | B10: Apple IAP 상품 등록 및 검증 | C10: App Store Connect 전 상품 등록. Sandbox 결제 테스트 | G10: 미착수
A11: [P0] 필수 | B11: Google Play Billing 상품 등록 및 검증 | C11: Play Console 전 상품 등록. 테스트 결제 검증 | G11: 미착수
A12: [P0] 필수 | B12: 영수증 검증 서버 | C12: Apple/Google 서버사이드 영수증 검증. 위변조 방지 | E12: 프로덕션 서버 구축 | G12: 미착수
A13: [P0] 필수 | B13: 결제 실패 시 복구 로직 | C13: 결제 성공→지급 실패 시 재지급 로직. 재화 유실 방지 | E13: 영수증 검증 서버 | G13: 미착수
A14: [P0] 필수 | B14: 확률형 아이템 확률 공시 페이지 | C14: 게임산업법 의무. 가챠 확률 공시 웹페이지 | E14: 가챠 확률 테이블 확정 | G14: 미착수
A15: [P0] 필수 | B15: 이용약관 / 개인정보처리방침 | C15: 법무 검토 완료된 다국어 약관. GDPR/CCPA 대응 | G15: 미착수
A16: [P0] 필수 | B16: 연령 등급 심사 (GRAC) | C16: 게임물관리위원회 등급 분류 필수 | G16: 미착수
A17: [P0] 필수 | B17: 음원 라이선스 계약 확인 | C17: 수록곡 전곡 디지털 사용 라이선스 확보 확인 | G17: 미착수
A18: [P0] 필수 | B18: 초상권/퍼블리시티권 계약 확인 | C18: TAEYANG, JEON SOMI, MEOVV, ADP 이미지 사용 계약 | G18: 미착수
A19: [P0] 필수 | B19: 가챠 확률 테이블 확정 | C19: 등급별 확률, 천장(Pity), 픽업 확률 최종 확정 | G19: 미착수
A20: [P0] 필수 | B20: 상점 상품 구성 확정 | C20: IAP 상품 목록, 가격 구간, 재화 구성 확정 | G20: 미착수
A21: [P0] 필수 | B21: 미성년자 결제 한도 시스템 | C21: 청소년 보호법 기반 월 결제 한도 제한 | E21: 영수증 검증 서버 | G21: 미착수
A22: [P0] 필수 | B22: 계정 연동/복구 프로세스 | C22: 게스트→SNS 연동, 계정 분실 시 복구 절차 | G22: 미착수
A23: [P0] 필수 | B23: 점검 모드 (Maintenance) 시스템 | C23: 긴급 점검 시 클라이언트 접속 차단 및 안내 | E23: 프로덕션 서버 구축 | G23: 미착수
A24: [P0] 필수 | B24: 사전등록 → 정식 전환 및 보상 지급 | C24: 사전등록 유저 보상 자동 지급 시스템 | E24: 프로덕션 서버 구축 | G24: 미착수
A25: [P0] 필수 | B25: 스토어 페이지 에셋 | C25: 스크린샷, 프리뷰 영상, 아이콘, 피쳐 그래픽 | G25: 미착수
A26: [P1] 중요 | B26: 튜토리얼 플로우 완성도 검증 | C26: FTUE 전체 플로우 이탈 포인트 검증. 신규 유저 첫 경험 | G26: 미착수
A27: [P1] 중요 | B27: 리듬게임 노트 싱크 검증 | C27: 전 수록곡 노트 타이밍/판정 검증. 디바이스별 레이턴시 | G27: 미착수
A28: [P1] 중요 | B28: 크리티컬 버그 픽스 | C28: Crash, ANR, 데이터 유실 등 치명적 버그 전수 수정 | G28: 미착수 | H28: 크래시율 목표 <0.5%
A29: [P1] 중요 | B29: 네트워크 예외 처리 | C29: 약한 네트워크, 끊김, Wi-Fi↔LTE 전환 시 안정성 | G29: 미착수
A30: [P1] 중요 | B30: 런칭 수록곡 리스트 확정 및 비트맵 완성 | C30: 전 수록곡 난이도별 비트맵 제작/검수 완료 | E30: 음원 라이선스 계약 | G30: 미착수
A31: [P1] 중요 | B31: 카드 밸런스 테이블 확정 | C31: 전체 카드 스탯, 스킬, 성장 밸런스 최종 확정 | G31: 미착수
A32: [P1] 중요 | B32: 아티스트별 카드 아트 완성 | C32: TAEYANG, JEON SOMI, MEOVV, ADP 전 등급 카드 아트 | G32: 미착수
A33: [P1] 중요 | B33: 다국어 텍스트 검증 | C33: 번역 누락, 오역, UI 오버플로우 전수 검사 | E33: 번역 대상 언어 확정 | G33: 미착수
A34: [P1] 중요 | B34: 번역 대상 언어 확정 및 번역 완료 | C34: 런칭 시 지원 언어 확정, 전체 텍스트 번역 | G34: 미착수
A35: [P1] 중요 | B35: 런칭 이벤트 기획 및 세팅 | C35: 런칭 보상, 출석 이벤트, 미션 이벤트 데이터 세팅 | E35: 달콤허브 운영툴 | G35: 미착수
A36: [P1] 중요 | B36: 달콤허브 운영툴 세팅 | C36: 게임 운영 관리 시스템 전체 기능 세팅 및 검증 | E36: 프로덕션 서버 구축 | G36: 미착수
A37: [P1] 중요 | B37: 공지사항/메일 발송 시스템 | C37: 인게임 공지, 우편함 보상 발송 시스템 검증 | E37: 달콤허브 운영툴 | G37: 미착수
A38: [P1] 중요 | B38: 달콤툴즈 세팅 | C38: 아트 리소스 관리 시스템 연동 및 검증 | G38: 미착수
A39: [P1] 중요 | B39: 런칭 마케팅 플랜 확정 및 집행 준비 | C39: UA 캠페인, 크리에이티브, 예산, 매체 플랜 | G39: 미착수
A40: [P1] 중요 | B40: 사전등록 캠페인 현황 관리 | C40: 사전등록 목표 달성 현황, 보상 단계 | G40: 미착수
A41: [P1] 중요 | B41: 트래킹 시스템 (MMP) 세팅 | C41: Adjust/AppsFlyer 어트리뷰션 트래킹 | G41: 미착수
...
